Workbook

Sheet الملخص
A1: تقرير جرد - PH29 - Moaz Pharmacy 29
A3: اسم الجرد | B3: جرد ٦ أكتوبر ٢٠٢٦ دواء
A4: نوع الجرد | B4: حسب التصنيف
A5: التصنيفات | B5: دواء
A6: الموردين | B6: -
A7: بداية الجرد | B7: 2026-10-06 03:17
A8: حالة التقرير | B8: نهائي - اتقفل 2026-10-06 03:25
A10: البند | B10: عدد الأصناف | C10: القيمة بسعر البيع
A11: يحتاج إعادة عد | B11: =COUNTIF('التفاصيل'!$J$2:$J$1606,"يحتاج إعادة عد") | C11: =SUMIF('التفاصيل'!$J$2:$J$1606,"يحتاج إعادة عد",'التفاصيل'!$I$2:$I$1606)
A12: مطابق | B12: =COUNTIF('التفاصيل'!$J$2:$J$1606,"مطابق") | C12: -
A13: عجز | B13: =COUNTIF('التفاصيل'!$J$2:$J$1606,"عجز") | C13: =SUMIF('التفاصيل'!$J$2:$J$1606,"عجز",'التفاصيل'!$I$2:$I$1606)
A14: لم يُجرد (موجود بالنظام ومتلقاش) | B14: =COUNTIF('التفاصيل'!$J$2:$J$1606,"لم يُجرد") | C14: =SUMIF('التفاصيل'!$J$2:$J$1606,"لم يُجرد",'التفاصيل'!$I$2:$I$1606)
A15: زيادة | B15: =COUNTIF('التفاصيل'!$J$2:$J$1606,"زيادة") | C15: =SUMIF('التفاصيل'!$J$2:$J$1606,"زيادة",'التفاصيل'!$I$2:$I$1606)
A16: رصيد سالب بالنظام | B16: =COUNTIF('التفاصيل'!$J$2:$J$1606,"رصيد سالب بالنظام") | C16: =SUMIF('التفاصيل'!$J$2:$J$1606,"رصيد سالب بالنظام",'التفاصيل'!$I$2:$I$1606)
A17: الإجمالي (القيمة = صافي الفرق من غير أصناف إعادة العد) | B17: =SUM(B11:B16) | C17: =SUM('التفاصيل'!$I$2:$I$1606)-SUMIF('التفاصيل'!$J$2:$J$1606,"يحتاج إعادة عد",'التفاصيل'!$I$2:$I$1606)
A18: نسبة المطابقة | B18: =IF(B17=0,0,B12/B17)
A20: ملاحظة: الدفتري وقت العد = رصيد جوليب الآن − صافي حركة المخزون بعد العد (مبيعات، مرتجعات، تحويلات، استلام، تسويات). "يحتاج إعادة عد" = الصنف اتحرك في جوليب بين أول وآخر مسحة ليه، ومش معروف الحركة كانت من مكان اتعد ولا لأ.

Sheet التفاصيل
A1: الكود | B1: الصنف | C1: التصنيف | D1: الباركود | E1: الدفتري وقت العد | F1: الكمية الفعلية | G1: الفرق | H1: سعر البيع | I1: قيمة الفرق بسعر البيع | J1: الحالة | K1: صافي حركة المخزون بعد العد | L1: رصيد جوليب الآن | M1: تفاصيل الحركة | N1: المواقع
A2: 0003663 | B2: [0003663] FLUDREX 24 TAB | C2: دواء | D2: 062850850015601723 | E2: =L2-K2 | F2: 132 | G2: =F2-E2 | H2: 12.3 | I2: =G2*H2 | J2: يحتاج إعادة عد | K2: -1 | L2: 132 | M2: أثناء عد الصنف (مش معروف من أنهي مكان): مبيعات −1 | N2: رف 4
A3: 0003369 | B3: [0003369] KLAVOX 1GM TAB 14 TAB | C3: دواء | D3: 06281086011508 | E3: =L3-K3 | F3: 0 | G3: =F3-E3 | H3: 70.65 | I3: =G3*H3 | J3: لم يُجرد | K3: 0 | L3: 171.5
A4: 00022817 | B4: [00022817] AVALON SALINOSE PLUS JET N. SPRAY 75 ML WASFA | C4: دواء | D4: 6285095009747 | E4: =L4-K4 | F4: 0 | G4: =F4-E4 | H4: 55 | I4: =G4*H4 | J4: لم يُجرد | K4: 0 | L4: 227
A5: 0003444 | B5: [0003444] HYMOX 500MG 20 CAPS | C5: دواء | E5: =L5-K5 | F5: 0 | G5: =F5-E5 | H5: 40.4 | I5: =G5*H5 | J5: لم يُجرد | K5: 0 | L5: 129.5
A6: 0004413 | B6: [0004413] ACILOC 20MG 14CAP WASFA | C6: دواء | D6: 06285128017503 | E6: =L6-K6 | F6: 0 | G6: =F6-E6 | H6: 45.95 | I6: =G6*H6 | J6: لم يُجرد | K6: 0 | L6: 218
A7: 0005677 | B7: [0005677] MEGAMOX 625 MG 20 TAB | C7: دواء | D7: 06285101000683 | E7: =L7-K7 | F7: 0 | G7: =F7-E7 | H7: 57.4 | I7: =G7*H7 | J7: لم يُجرد | K7: 0 | L7: 90
A8: 0005054 | B8: [0005054] ROFENAC D 50 MG 20 TAB | C8: دواء | D8: 06281086010457 | E8: =L8-K8 | F8: 0 | G8: =F8-E8 | H8: 29.55 | I8: =G8*H8 | J8: لم يُجرد | K8: 0 | L8: 163.25
A9: 00021703 | B9: [00021703] FUSIBACT B CREAM 30 GRAM WASFA | C9: دواء | D9: 06285128018005 | E9: =L9-K9 | F9: 0 | G9: =F9-E9 | H9: 25.8 | I9: =G9*H9 | J9: لم يُجرد | K9: 0 | L9: 238
A10: 00021654 | B10: [00021654] JP OMEGA3 1000MG 60CAP | C10: دواء | D10: 06285128015714 | E10: =L10-K10 | F10: 0 | G10: =F10-E10 | H10: 160 | I10: =G10*H10 | J10: لم يُجرد | K10: 0 | L10: 28
A11: 0003483 | B11: [0003483] HIQUIN 4% CREAM WASFA | C11: دواء | D11: 06285128000482 | E11: =L11-K11 | F11: 0 | G11: =F11-E11 | H11: 29.25 | I11: =G11*H11 | J11: لم يُجرد | K11: 0 | L11: 155
A12: 0004050 | B12: [0004050] ELICA M CREAM 30GM WASFA | C12: دواء | D12: 67021207260700 | E12: =L12-K12 | F12: 0 | G12: =F12-E12 | H12: 30.35 | I12: =G12*H12 | J12: لم يُجرد | K12: 0 | L12: 248
A13: 0003862 | B13: [0003862] EVRA TRANSDERMAL 3 PATCHES | C13: دواء | D13: 05997001375204 | E13: =L13-K13 | F13: 0 | G13: =F13-E13 | H13: 37.25 | I13: =G13*H13 | J13: لم يُجرد | K13: 0 | L13: 97
A14: 00016296 | B14: [00016296] HYFRESH SUD EYE GEL | C14: دواء | E14: =L14-K14 | F14: 0 | G14: =F14-E14 | H14: 46.1 | I14: =G14*H14 | J14: لم يُجرد | K14: 0 | L14: 72
A15: 00019041 | B15: [00019041] LORINASE D 2.5/120MG 20TAB | C15: دواء | E15: =L15-K15 | F15: 0 | G15: =F15-E15 | H15: 24.6 | I15: =G15*H15 | J15: لم يُجرد | K15: 0 | L15: 130
A16: 0004275 | B16: [0004275] CLARA 10MG 10TAB WASFA | C16: دواء | D16: 06285128000260 | E16: =L16-K16 | F16: 0 | G16: =F16-E16 | H16: 17.65 | I16: =G16*H16 | J16: لم يُجرد | K16: 0 | L16: 177
A17: 00039821 | B17: [00039821] AVOTRENE EMULGEL 100GM | C17: دواء | D17: 06285095010859 | E17: =L17-K17 | F17: 0 | G17: =F17-E17 | H17: 24.7 | I17: =G17*H17 | J17: لم يُجرد | K17: 0 | L17: 156
A18: 0003374 | B18: [0003374] KLAVOX 625 MG 20 TAB | C18: دواء | D18: 06281086010754 | E18: =L18-K18 | F18: 0 | G18: =F18-E18 | H18: 57.4 | I18: =G18*H18 | J18: لم يُجرد | K18: 0 | L18: 53
A19: 00020016 | B19: [00020016] JP HEMADID 200MG 120TAB WASFA | C19: دواء | E19: =L19-K19 | F19: 0 | G19: =F19-E19 | H19: 63.15 | I19: =G19*H19 | J19: لم يُجرد | K19: 0 | L19: 45
A20: 00014706 | B20: [00014706] JAVINO MOIST CREAM 100 GM | C20: دواء | D20: 06285128002707 | E20: =L20-K20 | F20: 0 | G20: =F20-E20 | H20: 85 | I20: =G20*H20 | J20: لم يُجرد | K20: 0 | L20: 40
A21: 0003863 | B21: [0003863] ERECTA 100MG F.C TAB | C21: دواء | D21: 06285128001021 | E21: =L21-K21 | F21: 0 | G21: =F21-E21 | H21: 48.55 | I21: =G21*H21 | J21: لم يُجرد | K21: 0 | L21: 76
A22: 0005491 | B22: [0005491] NEORIN 5MG 20 TAB | C22: دواء | D22: 06281086002513 | E22: =L22-K22 | F22: 0 | G22: =F22-E22 | H22: 25.9 | I22: =G22*H22 | J22: لم يُجرد | K22: 0 | L22: 91.5
A23: 0004805 | B23: [0004805] SNAFI 20 MG 4 TAB | C23: دواء | D23: 06281086001783 | E23: =L23-K23 | F23: 0 | G23: =F23-E23 | H23: 88.95 | I23: =G23*H23 | J23: لم يُجرد | K23: 0 | L23: 24.16
A24: 00024238 | B24: [00024238] JP CO Q10 200 MG 30CAP 487 | C24: دواء | D24: 6281200000487 | E24: =L24-K24 | F24: 0 | G24: =F24-E24 | H24: 188 | I24: =G24*H24 | J24: لم يُجرد | K24: 0 | L24: 11
A25: 0005834 | B25: [0005834] LUSTRAL 50MG 30 TAB | C25: دواء | E25: =L25-K25 | F25: 0 | G25: =F25-E25 | H25: 95.7 | I25: =G25*H25 | J25: لم يُجرد | K25: 0 | L25: 20
A26: 0005186 | B26: [0005186] RELAXON 250MG 30 CAPS WASFA | C26: دواء | D26: 010628512800076510ul | E26: =L26-K26 | F26: 0 | G26: =F26-E26 | H26: 27.75 | I26: =G26*H26 | J26: لم يُجرد | K26: 0 | L26: 114.67
A27: 0005649 | B27: [0005649] AVALON AVOHEX M/W 300ML | C27: دواء | D27: 6285095000294 | E27: =L27-K27 | F27: 0 | G27: =F27-E27 | H27: 37 | I27: =G27*H27 | J27: لم يُجرد | K27: 0 | L27: 94
A28: 0005663 | B28: [0005663] MEBO OINTMENT 15 GM | C28: دواء | D28: 06291100083367 | E28: =L28-K28 | F28: 0 | G28: =F28-E28 | H28: 45 | I28: =G28*H28 | J28: لم يُجرد | K28: 0 | L28: 39
A29: 0005616 | B29: [0005616] AVALON AVOGAIN 5% 50ML WASFA | C29: دواء | D29: 6285095004629 | E29: =L29-K29 | F29: 0 | G29: =F29-E29 | H29: 33.8 | I29: =G29*H29 | J29: لم يُجرد | K29: 0 | L29: 71
A30: 0005385 | B30: [0005385] AZI-ONCE 250MG 6 CAPS WASFA | C30: دواء | D30: 06285128000178 | E30: =L30-K30 | F30: 0 | G30: =F30-E30 | H30: 50.65 | I30: =G30*H30 | J30: لم يُجرد | K30: 0 | L30: 61
A31: 0004304 | B31: [0004304] CATAFAST 50MG 9 SACHETS | C31: دواء | D31: 07612797011409 | E31: =L31-K31 | F31: 0 | G31: =F31-E31 | H31: 18 | I31: =G31*H31 | J31: لم يُجرد | K31: 0 | L31: 99.5
A32: 0005647 | B32: [0005647] MARVELON 21 TAB***** | C32: دواء | D32: 00840164521337 | E32: =L32-K32 | F32: 0 | G32: =F32-E32 | H32: 14.6 | I32: =G32*H32 | J32: لم يُجرد | K32: 0 | L32: 99
A33: 0005242 | B33: [0005242] PRIMOLUT N 5 MG 30 TAB***** | C33: دواء | D33: 06285074004145 | E33: =L33-K33 | F33: 0 | G33: =F33-E33 | H33: 18.4 | I33: =G33*H33 | J33: لم يُجرد | K33: 0 | L33: 91
A34: 0004485 | B34: [0004485] ZIMAX 250 MG 6 CAP | C34: دواء | E34: =L34-K34 | F34: 0 | G34: =F34-E34 | H34: 62.8 | I34: =G34*H34 | J34: لم يُجرد | K34: 0 | L34: 26
A35: 00020484 | B35: [00020484] REXOFIL 20 MG 4TAB | C35: دواء | E35: =L35-K35 | F35: 0 | G35: =F35-E35 | H35: 64.85 | I35: =G35*H35 | J35: لم يُجرد | K35: 0 | L35: 76.75
A36: 00047345 | B36: [00047345] TOUJEO 300 IUML SOLU FOR INJ PREFILLED 5 PEN | C36: دواء | E36: =L36-K36 | F36: 0 | G36: =F36-E36 | H36: 356.35 | I36: =G36*H36 | J36: لم يُجرد | K36: 0 | L36: 4
A37: 00014742 | B37: [00014742] SNAFI 5 MG 30 TAB | C37: دواء | E37: =L37-K37 | F37: 0 | G37: =F37-E37 | H37: 136.15 | I37: =G37*H37 | J37: لم يُجرد | K37: 0 | L37: 9.75
A38: 0003373 | B38: [0003373] KLAVOX 457MG SUSPENSION 70ML | C38: دواء | D38: 06281086011751 | E38: =L38-K38 | F38: 0 | G38: =F38-E38 | H38: 26.65 | I38: =G38*H38 | J38: لم يُجرد | K38: 0 | L38: 52
A39: 0005855 | B39: [0005855] AVALON AVOCOM-M CREAM 50 G | C39: دواء | D39: 06285095008344 | E39: =L39-K39 | F39: 0 | G39: =F39-E39 | H39: 37.25 | I39: =G39*H39 | J39: لم يُجرد | K39: 0 | L39: 37
A40: 00026208 | B40: [00026208] PRIMA D 5000 IU 60CAP WASFA | C40: دواء | E40: =L40-K40 | F40: 0 | G40: =F40-E40 | H40: 33 | I40: =G40*H40 | J40: لم يُجرد | K40: 0 | L40: 57
...

Sheet باركود غير معرّف
A1: الباركود | B1: الكمية | C1: أول مسح | D1: المواقع

Sheet سجل المسح
A1: # | B1: الوقت | C1: الباركود | D1: الكود | E1: الصنف | F1: الكمية | G1: النوع | H1: الموقع | I1: القائم بالجرد
A2: 1 | B2: 2026-10-06 03:17 | C2: 0005454 | D2: 0005454 | E2: [0005454] NIZORAL SHAMPOO 100ML | F2: 31 | G2: مسح | I2: يحى زقزوق
A3: 2 | B3: 2026-10-06 03:22 | C3: 0003663 | D3: 0003663 | E3: [0003663] FLUDREX 24 TAB | F3: 100 | G3: مسح | I3: يحى زقزوق
A4: 3 | B4: 2026-10-06 03:23 | C4: 0003663 | D4: 0003663 | E4: [0003663] FLUDREX 24 TAB | F4: 32 | G4: مسح | H4: رف 4 | I4: يحى زقزوق
